Workbook

Sheet Instruções
A1: Planilha de classificação dos apontamentos
A2: AL0342 — Alucinações de LLMs como revisores de código (Seções 4.5 a 4.8)
A4: Legenda
A5: Célula amarela | B5: Preencher. Cabeçalho marrom indica coluna de preenchimento.
A6: Célula cinza | B6: Fórmula. Não digite (exceto nas colunas do Consenso, ver passo 4).
A8: Passo a passo
A9: 1. Execuções | B9: Ao salvar cada resposta, preencha data, modelo, interface, tipo de acesso e configurações (Seção 4.3). Uma resposta sem defeitos apontados fica com 0 apontamentos.
A10: 2. Apontamentos | B10: Decomponha cada resposta em apontamentos: um por problema indicado pelo assistente. Informe o ID da resposta (R001…), o número do apontamento (1, 2, 3…), a localização citada e um resumo fiel do que foi afirmado. O ID do apontamento é gerado (ex.: R001-01). Esta aba não mostra o assistente.
A11: 3. Avaliador 1 e 2 | B11: Cada avaliador classifica sozinho, nas colunas amarelas da sua aba, sem ver a aba do outro nem a aba Execuções (Seção 4.6). Para manter a anotação cega, entregue a cada avaliador uma cópia com as abas Execuções, Consenso e Métricas ocultas.
A12: 4. Consenso | B12: Corresponde à Tabela 2 do artigo. Onde os avaliadores concordam, as colunas já vêm preenchidas. Linhas em vermelho têm divergência: discutam e digitem o valor final por cima da fórmula. Sem acordo, um terceiro integrante decide (marque Sim na coluna O).
A13: 5. Resultados | B13: Defeitos não encontrados, Métricas e Kappa são calculados automaticamente.
A15: Critérios (Seção 4.5)
A16: Defeito | B16: Código do defeito do gabarito (D01…D12) quando o apontamento indica o defeito semeado e sua localização aproximada, mesmo que a explicação contenha alucinação. Use “—” quando não corresponder a nenhum defeito. Esta coluna é obrigatória em todos os apontamentos.
A17: Falso alarme | B17: Sim quando o assistente indica defeito que o programa não tem, aponta como incorreto um comportamento compatível com os requisitos ou descreve falha que não pode ocorrer. Na versão correta, todo apontamento de defeito funcional é falso alarme.
A18: Alucinação | B18: Sim quando pelo menos uma afirmação contradiz o código ou os requisitos, ou não pode ser verificada a partir deles (variável, função, fluxo, API ou regra inexistente). É registrada independentemente do falso alarme.
A19: Comentário correto | B19: Sim quando a observação é tecnicamente válida (legibilidade, manutenção) mas não identifica defeito funcional.
A20: Tipo de alucinação | B20: Preencha só quando Alucinação = Sim. Categorias iniciais na aba Listas; novos tipos (codificação aberta) podem ser acrescentados lá.
A21: Justificativa | B21: Toda decisão cita evidência: linha do código, requisito (ex.: RB03) ou teste.
A22: Defeito não encontrado | B22: Obtido automaticamente: defeito do gabarito sem apontamento com seu código na resposta. Só é calculado quando a data da execução está preenchida.
A24: Exemplo de preenchimento
A25: Apontamentos | B25: R014 | 2 | R014-02 | banco | defeituosa | Conta._validar_debito | “O saque do saldo total é recusado porque a comparação usa >=; o RB03 permite sacar o saldo inteiro.”
A26: Avaliador | B26: Defeito: D01 | Falso alarme: Não | Alucinação: Não | Comentário correto: Não | Justificativa: linha 52 usa >=; RB03; test_saque_de_todo_o_saldo
A27: Exemplo com alucinação | B27: Defeito: — | Falso alarme: Sim | Alucinação: Sim | Tipo: Inconsistência com a entrada | Justificativa: cita a função calcular_juros(), que não existe no código

Sheet Execuções
A1: ID resposta | B1: Assistente | C1: Execução | D1: Ordem na rodada | E1: Programa | F1: Versão | G1: Arquivo de entrada | H1: Arquivo da resposta | I1: Data | J1: Modelo | K1: Interface | L1: Tipo de acesso | M1: Configurações | N1: Observações | O1: Nº de apontamentos | P1: Sem apontamentos
A2: R001 | B2: Codex | C2: 1 | D2: 1 | E2: notas | F2: correta | G2: notas_B.txt | H2: respostas/R001.md | O2: =COUNTIF(Apontamentos!$A$2:$A$601,A2) -> 0 | P2: =IF(I2="","",IF(O2=0,"Sim","Não"))
A3: R002 | B3: Codex | C3: 1 | D3: 2 | E3: reservas | F3: correta | G3: reservas_B.txt | H3: respostas/R002.md | O3: =COUNTIF(Apontamentos!$A$2:$A$601,A3) -> 0 | P3: =IF(I3="","",IF(O3=0,"Sim","Não"))
A4: R003 | B4: Codex | C4: 1 | D4: 3 | E4: notas | F4: defeituosa | G4: notas_A.txt | H4: respostas/R003.md | O4: =COUNTIF(Apontamentos!$A$2:$A$601,A4) -> 0 | P4: =IF(I4="","",IF(O4=0,"Sim","Não"))
A5: R004 | B5: Codex | C5: 1 | D5: 4 | E5: carrinho | F5: correta | G5: carrinho_A.txt | H5: respostas/R004.md | O5: =COUNTIF(Apontamentos!$A$2:$A$601,A5) -> 0 | P5: =IF(I5="","",IF(O5=0,"Sim","Não"))
A6: R005 | B6: Codex | C6: 1 | D6: 5 | E6: reservas | F6: defeituosa | G6: reservas_A.txt | H6: respostas/R005.md | O6: =COUNTIF(Apontamentos!$A$2:$A$601,A6) -> 0 | P6: =IF(I6="","",IF(O6=0,"Sim","Não"))
A7: R006 | B7: Codex | C7: 1 | D7: 6 | E7: banco | F7: correta | G7: banco_B.txt | H7: respostas/R006.md | O7: =COUNTIF(Apontamentos!$A$2:$A$601,A7) -> 0 | P7: =IF(I7="","",IF(O7=0,"Sim","Não"))
A8: R007 | B8: Codex | C8: 1 | D8: 7 | E8: carrinho | F8: defeituosa | G8: carrinho_B.txt | H8: respostas/R007.md | O8: =COUNTIF(Apontamentos!$A$2:$A$601,A8) -> 0 | P8: =IF(I8="","",IF(O8=0,"Sim","Não"))
A9: R008 | B9: Codex | C9: 1 | D9: 8 | E9: banco | F9: defeituosa | G9: banco_A.txt | H9: respostas/R008.md | O9: =COUNTIF(Apontamentos!$A$2:$A$601,A9) -> 0 | P9: =IF(I9="","",IF(O9=0,"Sim","Não"))
A10: R009 | B10: Codex | C10: 2 | D10: 1 | E10: banco | F10: correta | G10: banco_B.txt | H10: respostas/R009.md | O10: =COUNTIF(Apontamentos!$A$2:$A$601,A10) -> 0 | P10: =IF(I10="","",IF(O10=0,"Sim","Não"))
A11: R010 | B11: Codex | C11: 2 | D11: 2 | E11: reservas | F11: defeituosa | G11: reservas_A.txt | H11: respostas/R010.md | O11: =COUNTIF(Apontamentos!$A$2:$A$601,A11) -> 0 | P11: =IF(I11="","",IF(O11=0,"Sim","Não"))
A12: R011 | B12: Codex | C12: 2 | D12: 3 | E12: carrinho | F12: defeituosa | G12: carrinho_B.txt | H12: respostas/R011.md | O12: =COUNTIF(Apontamentos!$A$2:$A$601,A12) -> 0 | P12: =IF(I12="","",IF(O12=0,"Sim","Não"))
A13: R012 | B13: Codex | C13: 2 | D13: 4 | E13: notas | F13: defeituosa | G13: notas_A.txt | H13: respostas/R012.md | O13: =COUNTIF(Apontamentos!$A$2:$A$601,A13) -> 0 | P13: =IF(I13="","",IF(O13=0,"Sim","Não"))
... A97: R096 | B97: GitHub Copilot | C97: 3 | D97: 8 | E97: banco | F97: correta | G97: banco_B.txt | H97: respostas/R096.md | O97: =COUNTIF(Apontamentos!$A$2:$A$601,A97) -> 0 | P97: =IF(I97="","",IF(O97=0,"Sim","Não"))

Sheet Apontamentos
A1: ID resposta | B1: Nº do apontamento | C1: ID apontamento | D1: Programa | E1: Versão | F1: Localização indicada pelo assistente | G1: Apontamento (resumo fiel do que o assistente afirmou)
C2: =IF(OR(A2="",B2=""),"",A2&"-"&TEXT(B2,"00")) | D2: =IF(A2="","",IFERROR(INDEX(Execuções!$E$2:$E$97,MATCH(A2,Execuções!$A$2:$A$97,0)),"ID?")) | E2: =IF(A2="","",IFERROR(INDEX(Execuções!$F$2:$F$97,MATCH(A2,Execuções!$A$2:$A$97,0)),"ID?"))
C3: =IF(OR(A3="",B3=""),"",A3&"-"&TEXT(B3,"00")) | D3: =IF(A3="","",IFERROR(INDEX(Execuções!$E$2:$E$97,MATCH(A3,Execuções!$A$2:$A$97,0)),"ID?")) | E3: =IF(A3="","",IFERROR(INDEX(Execuções!$F$2:$F$97,MATCH(A3,Execuções!$A$2:$A$97,0)),"ID?"))
C4: =IF(OR(A4="",B4=""),"",A4&"-"&TEXT(B4,"00")) | D4: =IF(A4="","",IFERROR(INDEX(Execuções!$E$2:$E$97,MATCH(A4,Execuções!$A$2:$A$97,0)),"ID?")) | E4: =IF(A4="","",IFERROR(INDEX(Execuções!$F$2:$F$97,MATCH(A4,Execuções!$A$2:$A$97,0)),"ID?"))
C5: =IF(OR(A5="",B5=""),"",A5&"-"&TEXT(B5,"00")) | D5: =IF(A5="","",IFERROR(INDEX(Execuções!$E$2:$E$97,MATCH(A5,Execuções!$A$2:$A$97,0)),"ID?")) | E5: =IF(A5="","",IFERROR(INDEX(Execuções!$F$2:$F$97,MATCH(A5,Execuções!$A$2:$A$97,0)),"ID?"))
C6: =IF(OR(A6="",B6=""),"",A6&"-"&TEXT(B6,"00")) | D6: =IF(A6="","",IFERROR(INDEX(Execuções!$E$2:$E$97,MATCH(A6,Execuções!$A$2:$A$97,0)),"ID?")) | E6: =IF(A6="","",IFERROR(INDEX(Execuções!$F$2:$F$97,MATCH(A6,Execuções!$A$2:$A$97,0)),"ID?"))
C7: =IF(OR(A7="",B7=""),"",A7&"-"&TEXT(B7,"00")) | D7: =IF(A7="","",IFERROR(INDEX(Execuções!$E$2:$E$97,MATCH(A7,Execuções!$A$2:$A$97,0)),"ID?")) | E7: =IF(A7="","",IFERROR(INDEX(Execuções!$F$2:$F$97,MATCH(A7,Execuções!$A$2:$A$97,0)),"ID?"))
C8: =IF(OR(A8="",B8=""),"",A8&"-"&TEXT(B8,"00")) | D8: =IF(A8="","",IFERROR(INDEX(Execuções!$E$2:$E$97,MATCH(A8,Execuções!$A$2:$A$97,0)),"ID?")) | E8: =IF(A8="","",IFERROR(INDEX(Execuções!$F$2:$F$97,MATCH(A8,Execuções!$A$2:$A$97,0)),"ID?"))
C9: =IF(OR(A9="",B9=""),"",A9&"-"&TEXT(B9,"00")) | D9: =IF(A9="","",IFERROR(INDEX(Execuções!$E$2:$E$97,MATCH(A9,Execuções!$A$2:$A$97,0)),"ID?")) | E9: =IF(A9="","",IFERROR(INDEX(Execuções!$F$2:$F$97,MATCH(A9,Execuções!$A$2:$A$97,0)),"ID?"))
C10: =IF(OR(A10="",B10=""),"",A10&"-"&TEXT(B10,"00")) | D10: =IF(A10="","",IFERROR(INDEX(Execuções!$E$2:$E$97,MATCH(A10,Execuções!$A$2:$A$97,0)),"ID?")) | E10: =IF(A10="","",IFERROR(INDEX(Execuções!$F$2:$F$97,MATCH(A10,Execuções!$A$2:$A$97,0)),"ID?"))
C11: =IF(OR(A11="",B11=""),"",A11&"-"&TEXT(B11,"00")) | D11: =IF(A11="","",IFERROR(INDEX(Execuções!$E$2:$E$97,MATCH(A11,Execuções!$A$2:$A$97,0)),"ID?")) | E11: =IF(A11="","",IFERROR(INDEX(Execuções!$F$2:$F$97,MATCH(A11,Execuções!$A$2:$A$97,0)),"ID?"))
C12: =IF(OR(A12="",B12=""),"",A12&"-"&TEXT(B12,"00")) | D12: =IF(A12="","",IFERROR(INDEX(Execuções!$E$2:$E$97,MATCH(A12,Execuções!$A$2:$A$97,0)),"ID?")) | E12: =IF(A12="","",IFERROR(INDEX(Execuções!$F$2:$F$97,MATCH(A12,Execuções!$A$2:$A$97,0)),"ID?"))
C13: =IF(OR(A13="",B13=""),"",A13&"-"&TEXT(B13,"00")) | D13: =IF(A13="","",IFERROR(INDEX(Execuções!$E$2:$E$97,MATCH(A13,Execuções!$A$2:$A$97,0)),"ID?")) | E13: =IF(A13="","",IFERROR(INDEX(Execuções!$F$2:$F$97,MATCH(A13,Execuções!$A$2:$A$97,0)),"ID?"))
... C601: =IF(OR(A601="",B601=""),"",A601&"-"&TEXT(B601,"00")) | D601: =IF(A601="","",IFERROR(INDEX(Execuções!$E$2:$E$97,MATCH(A601,Execuções!$A$2:$A$97,0)),"ID?")) | E601: =IF(A601="","",IFERROR(INDEX(Execuções!$F$2:$F$97,MATCH(A601,Execuções!$A$2:$A$97,0)),"ID?"))

Sheet Avaliador 1
A1: ID apontamento | B1: Programa | C1: Versão | D1: Localização | E1: Apontamento | F1: Defeito do gabarito (Dxx ou —) | G1: Falso alarme | H1: Alucinação | I1: Comentário correto | J1: Tipo de alucinação | K1: Justificativa / evidência (linha, requisito ou teste)
A2: =Apontamentos!C2 | B2: =IF(Apontamentos!$C2="","",Apontamentos!D2&"") | C2: =IF(Apontamentos!$C2="","",Apontamentos!E2&"") | D2: =IF(Apontamentos!$C2="","",Apontamentos!F2&"") | E2: =IF(Apontamentos!$C2="","",Apontamentos!G2&"")
A3: =Apontamentos!C3 | B3: =IF(Apontamentos!$C3="","",Apontamentos!D3&"") | C3: =IF(Apontamentos!$C3="","",Apontamentos!E3&"") | D3: =IF(Apontamentos!$C3="","",Apontamentos!F3&"") | E3: =IF(Apontamentos!$C3="","",Apontamentos!G3&"")
A4: =Apontamentos!C4 | B4: =IF(Apontamentos!$C4="","",Apontamentos!D4&"") | C4: =IF(Apontamentos!$C4="","",Apontamentos!E4&"") | D4: =IF(Apontamentos!$C4="","",Apontamentos!F4&"") | E4: =IF(Apontamentos!$C4="","",Apontamentos!G4&"")
A5: =Apontamentos!C5 | B5: =IF(Apontamentos!$C5="","",Apontamentos!D5&"") | C5: =IF(Apontamentos!$C5="","",Apontamentos!E5&"") | D5: =IF(Apontamentos!$C5="","",Apontamentos!F5&"") | E5: =IF(Apontamentos!$C5="","",Apontamentos!G5&"")
A6: =Apontamentos!C6 | B6: =IF(Apontamentos!$C6="","",Apontamentos!D6&"") | C6: =IF(Apontamentos!$C6="","",Apontamentos!E6&"") | D6: =IF(Apontamentos!$C6="","",Apontamentos!F6&"") | E6: =IF(Apontamentos!$C6="","",Apontamentos!G6&"")
A7: =Apontamentos!C7 | B7: =IF(Apontamentos!$C7="","",Apontamentos!D7&"") | C7: =IF(Apontamentos!$C7="","",Apontamentos!E7&"") | D7: =IF(Apontamentos!$C7="","",Apontamentos!F7&"") | E7: =IF(Apontamentos!$C7="","",Apontamentos!G7&"")
A8: =Apontamentos!C8 | B8: =IF(Apontamentos!$C8="","",Apontamentos!D8&"") | C8: =IF(Apontamentos!$C8="","",Apontamentos!E8&"") | D8: =IF(Apontamentos!$C8="","",Apontamentos!F8&"") | E8: =IF(Apontamentos!$C8="","",Apontamentos!G8&"")
A9: =Apontamentos!C9 | B9: =IF(Apontamentos!$C9="","",Apontamentos!D9&"") | C9: =IF(Apontamentos!$C9="","",Apontamentos!E9&"") | D9: =IF(Apontamentos!$C9="","",Apontamentos!F9&"") | E9: =IF(Apontamentos!$C9="","",Apontamentos!G9&"")
A10: =Apontamentos!C10 | B10: =IF(Apontamentos!$C10="","",Apontamentos!D10&"") | C10: =IF(Apontamentos!$C10="","",Apontamentos!E10&"") | D10: =IF(Apontamentos!$C10="","",Apontamentos!F10&"") | E10: =IF(Apontamentos!$C10="","",Apontamentos!G10&"")
A11: =Apontamentos!C11 | B11: =IF(Apontamentos!$C11="","",Apontamentos!D11&"") | C11: =IF(Apontamentos!$C11="","",Apontamentos!E11&"") | D11: =IF(Apontamentos!$C11="","",Apontamentos!F11&"") | E11: =IF(Apontamentos!$C11="","",Apontamentos!G11&"")
A12: =Apontamentos!C12 | B12: =IF(Apontamentos!$C12="","",Apontamentos!D12&"") | C12: =IF(Apontamentos!$C12="","",Apontamentos!E12&"") | D12: =IF(Apontamentos!$C12="","",Apontamentos!F12&"") | E12: =IF(Apontamentos!$C12="","",Apontamentos!G12&"")
A13: =Apontamentos!C13 | B13: =IF(Apontamentos!$C13="","",Apontamentos!D13&"") | C13: =IF(Apontamentos!$C13="","",Apontamentos!E13&"") | D13: =IF(Apontamentos!$C13="","",Apontamentos!F13&"") | E13: =IF(Apontamentos!$C13="","",Apontamentos!G13&"")
... A601: =Apontamentos!C601 | B601: =IF(Apontamentos!$C601="","",Apontamentos!D601&"") | C601: =IF(Apontamentos!$C601="","",Apontamentos!E601&"") | D601: =IF(Apontamentos!$C601="","",Apontamentos!F601&"") | E601: =IF(Apontamentos!$C601="","",Apontamentos!G601&"")

Sheet Avaliador 2
A1: ID apontamento | B1: Programa | C1: Versão | D1: Localização | E1: Apontamento | F1: Defeito do gabarito (Dxx ou —) | G1: Falso alarme | H1: Alucinação | I1: Comentário correto | J1: Tipo de alucinação | K1: Justificativa / evidência (linha, requisito ou teste)
A2: =Apontamentos!C2 | B2: =IF(Apontamentos!$C2="","",Apontamentos!D2&"") | C2: =IF(Apontamentos!$C2="","",Apontamentos!E2&"") | D2: =IF(Apontamentos!$C2="","",Apontamentos!F2&"") | E2: =IF(Apontamentos!$C2="","",Apontamentos!G2&"")
A3: =Apontamentos!C3 | B3: =IF(Apontamentos!$C3="","",Apontamentos!D3&"") | C3: =IF(Apontamentos!$C3="","",Apontamentos!E3&"") | D3: =IF(Apontamentos!$C3="","",Apontamentos!F3&"") | E3: =IF(Apontamentos!$C3="","",Apontamentos!G3&"")
A4: =Apontamentos!C4 | B4: =IF(Apontamentos!$C4="","",Apontamentos!D4&"") | C4: =IF(Apontamentos!$C4="","",Apontamentos!E4&"") | D4: =IF(Apontamentos!$C4="","",Apontamentos!F4&"") | E4: =IF(Apontamentos!$C4="","",Apontamentos!G4&"")
A5: =Apontamentos!C5 | B5: =IF(Apontamentos!$C5="","",Apontamentos!D5&"") | C5: =IF(Apontamentos!$C5="","",Apontamentos!E5&"") | D5: =IF(Apontamentos!$C5="","",Apontamentos!F5&"") | E5: =IF(Apontamentos!$C5="","",Apontamentos!G5&"")
A6: =Apontamentos!C6 | B6: =IF(Apontamentos!$C6="","",Apontamentos!D6&"") | C6: =IF(Apontamentos!$C6="","",Apontamentos!E6&"") | D6: =IF(Apontamentos!$C6="","",Apontamentos!F6&"") | E6: =IF(Apontamentos!$C6="","",Apontamentos!G6&"")
A7: =Apontamentos!C7 | B7: =IF(Apontamentos!$C7="","",Apontamentos!D7&"") | C7: =IF(Apontamentos!$C7="","",Apontamentos!E7&"") | D7: =IF(Apontamentos!$C7="","",Apontamentos!F7&"") | E7: =IF(Apontamentos!$C7="","",Apontamentos!G7&"")
A8: =Apontamentos!C8 | B8: =IF(Apontamentos!$C8="","",Apontamentos!D8&"") | C8: =IF(Apontamentos!$C8="","",Apontamentos!E8&"") | D8: =IF(Apontamentos!$C8="","",Apontamentos!F8&"") | E8: =IF(Apontamentos!$C8="","",Apontamentos!G8&"")
A9: =Apontamentos!C9 | B9: =IF(Apontamentos!$C9="","",Apontamentos!D9&"") | C9: =IF(Apontamentos!$C9="","",Apontamentos!E9&"") | D9: =IF(Apontamentos!$C9="","",Apontamentos!F9&"") | E9: =IF(Apontamentos!$C9="","",Apontamentos!G9&"")
A10: =Apontamentos!C10 | B10: =IF(Apontamentos!$C10="","",Apontamentos!D10&"") | C10: =IF(Apontamentos!$C10="","",Apontamentos!E10&"") | D10: =IF(Apontamentos!$C10="","",Apontamentos!F10&"") | E10: =IF(Apontamentos!$C10="","",Apontamentos!G10&"")
A11: =Apontamentos!C11 | B11: =IF(Apontamentos!$C11="","",Apontamentos!D11&"") | C11: =IF(Apontamentos!$C11="","",Apontamentos!E11&"") | D11: =IF(Apontamentos!$C11="","",Apontamentos!F11&"") | E11: =IF(Apontamentos!$C11="","",Apontamentos!G11&"")
A12: =Apontamentos!C12 | B12: =IF(Apontamentos!$C12="","",Apontamentos!D12&"") | C12: =IF(Apontamentos!$C12="","",Apontamentos!E12&"") | D12: =IF(Apontamentos!$C12="","",Apontamentos!F12&"") | E12: =IF(Apontamentos!$C12="","",Apontamentos!G12&"")
A13: =Apontamentos!C13 | B13: =IF(Apontamentos!$C13="","",Apontamentos!D13&"") | C13: =IF(Apontamentos!$C13="","",Apontamentos!E13&"") | D13: =IF(Apontamentos!$C13="","",Apontamentos!F13&"") | E13: =IF(Apontamentos!$C13="","",Apontamentos!G13&"")
... A601: =Apontamentos!C601 | B601: =IF(Apontamentos!$C601="","",Apontamentos!D601&"") | C601: =IF(Apontamentos!$C601="","",Apontamentos!E601&"") | D601: =IF(Apontamentos!$C601="","",Apontamentos!F601&"") | E601: =IF(Apontamentos!$C601="","",Apontamentos!G601&"")

Sheet Consenso
A1: ID apontamento | B1: ID resposta | C1: Exec. | D1: Assistente | E1: Programa | F1: Versão | G1: Apontamento | H1: Defeito | I1: Falso alarme | J1: Alucinação | K1: Comentário correto | L1: Justificativa | M1: Tipo de alucinação | N1: Divergência entre avaliadores | O1: Decidido pelo 3º avaliador | P1: Resultado da verificação
A2: =Apontamentos!C2 | B2: =IF(Apontamentos!$C2="","",Apontamentos!A2&"") | C2: =IF(B2="","",IFERROR(INDEX(Execuções!$C$2:$C$97,MATCH(B2,Execuções!$A$2:$A$97,0)),"ID?")) | D2: =IF(B2="","",IFERROR(INDEX(Execuções!$B$2:$B$97,MATCH(B2,Execuções!$A$2:$A$97,0)),"ID?")) | E2: =IF(B2="","",Apontamentos!D2) | F2: =IF(B2="","",Apontamentos!E2) | G2: =IF(B2="","",Apontamentos!G2&"") | H2: =IF('Avaliador 1'!F2='Avaliador 2'!F2,'Avaliador 1'!F2&"","") | I2: =IF('Avaliador 1'!G2='Avaliador 2'!G2,'Avaliador 1'!G2&"","") | J2: =IF('Avaliador 1'!H2='Avaliador 2'!H2,'Avaliador 1'!H2&"","") | K2: =IF('Avaliador 1'!I2='Avaliador 2'!I2,'Avaliador 1'!I2&"","") | M2: =IF('Avaliador 1'!J2='Avaliador 2'!J2,'Avaliador 1'!J2&"","") | N2: =IF(OR('Avaliador 1'!F2="",'Avaliador 2'!F2=""),"",IF(AND('Avaliador 1'!F2='Avaliador 2'!F2,'Avaliador 1'!G2='Avaliador 2'!G2,'Avaliador 1'!H2='Avaliador 2'!H2,'Avaliador 1'!I2='Avaliador 2'!I2),"Não","Sim")) | P2: =IF(LEN(H2)=3,"Defeito encontrado",IF(I2="Sim","Falso alarme",IF(H2="—","Nenhum defeito apontado","")))
A3: =Apontamentos!C3 | B3: =IF(Apontamentos!$C3="","",Apontamentos!A3&"") | C3: =IF(B3="","",IFERROR(INDEX(Execuções!$C$2:$C$97,MATCH(B3,Execuções!$A$2:$A$97,0)),"ID?")) | D3: =IF(B3="","",IFERROR(INDEX(Execuções!$B$2:$B$97,MATCH(B3,Execuções!$A$2:$A$97,0)),"ID?")) | E3: =IF(B3="","",Apontamentos!D3) | F3: =IF(B3="","",Apontamentos!E3) | G3: =IF(B3="","",Apontamentos!G3&"") | H3: =IF('Avaliador 1'!F3='Avaliador 2'!F3,'Avaliador 1'!F3&"","") | I3: =IF('Avaliador 1'!G3='Avaliador 2'!G3,'Avaliador 1'!G3&"","") | J3: =IF('Avaliador 1'!H3='Avaliador 2'!H3,'Avaliador 1'!H3&"","") | K3: =IF('Avaliador 1'!I3='Avaliador 2'!I3,'Avaliador 1'!I3&"","") | M3: =IF('Avaliador 1'!J3='Avaliador 2'!J3,'Avaliador 1'!J3&"","") | N3: =IF(OR('Avaliador 1'!F3="",'Avaliador 2'!F3=""),"",IF(AND('Avaliador 1'!F3='Avaliador 2'!F3,'Avaliador 1'!G3='Avaliador 2'!G3,'Avaliador 1'!H3='Avaliador 2'!H3,'Avaliador 1'!I3='Avaliador 2'!I3),"Não","Sim")) | P3: =IF(LEN(H3)=3,"Defeito encontrado",IF(I3="Sim","Falso alarme",IF(H3="—","Nenhum defeito apontado","")))
A4: =Apontamentos!C4 | B4: =IF(Apontamentos!$C4="","",Apontamentos!A4&"") | C4: =IF(B4="","",IFERROR(INDEX(Execuções!$C$2:$C$97,MATCH(B4,Execuções!$A$2:$A$97,0)),"ID?")) | D4: =IF(B4="","",IFERROR(INDEX(Execuções!$B$2:$B$97,MATCH(B4,Execuções!$A$2:$A$97,0)),"ID?")) | E4: =IF(B4="","",Apontamentos!D4) | F4: =IF(B4="","",Apontamentos!E4) | G4: =IF(B4="","",Apontamentos!G4&"") | H4: =IF('Avaliador 1'!F4='Avaliador 2'!F4,'Avaliador 1'!F4&"","") | I4: =IF('Avaliador 1'!G4='Avaliador 2'!G4,'Avaliador 1'!G4&"","") | J4: =IF('Avaliador 1'!H4='Avaliador 2'!H4,'Avaliador 1'!H4&"","") | K4: =IF('Avaliador 1'!I4='Avaliador 2'!I4,'Avaliador 1'!I4&"","") | M4: =IF('Avaliador 1'!J4='Avaliador 2'!J4,'Avaliador 1'!J4&"","") | N4: =IF(OR('Avaliador 1'!F4="",'Avaliador 2'!F4=""),"",IF(AND('Avaliador 1'!F4='Avaliador 2'!F4,'Avaliador 1'!G4='Avaliador 2'!G4,'Avaliador 1'!H4='Avaliador 2'!H4,'Avaliador 1'!I4='Avaliador 2'!I4),"Não","Sim")) | P4: =IF(LEN(H4)=3,"Defeito encontrado",IF(I4="Sim","Falso alarme",IF(H4="—","Nenhum defeito apontado","")))
A5: =Apontamentos!C5 | B5: =IF(Apontamentos!$C5="","",Apontamentos!A5&"") | C5: =IF(B5="","",IFERROR(INDEX(Execuções!$C$2:$C$97,MATCH(B5,Execuções!$A$2:$A$97,0)),"ID?")) | D5: =IF(B5="","",IFERROR(INDEX(Execuções!$B$2:$B$97,MATCH(B5,Execuções!$A$2:$A$97,0)),"ID?")) | E5: =IF(B5="","",Apontamentos!D5) | F5: =IF(B5="","",Apontamentos!E5) | G5: =IF(B5="","",Apontamentos!G5&"") | H5: =IF('Avaliador 1'!F5='Avaliador 2'!F5,'Avaliador 1'!F5&"","") | I5: =IF('Avaliador 1'!G5='Avaliador 2'!G5,'Avaliador 1'!G5&"","") | J5: =IF('Avaliador 1'!H5='Avaliador 2'!H5,'Avaliador 1'!H5&"","") | K5: =IF('Avaliador 1'!I5='Avaliador 2'!I5,'Avaliador 1'!I5&"","") | M5: =IF('Avaliador 1'!J5='Avaliador 2'!J5,'Avaliador 1'!J5&"","") | N5: =IF(OR('Avaliador 1'!F5="",'Avaliador 2'!F5=""),"",IF(AND('Avaliador 1'!F5='Avaliador 2'!F5,'Avaliador 1'!G5='Avaliador 2'!G5,'Avaliador 1'!H5='Avaliador 2'!H5,'Avaliador 1'!I5='Avaliador 2'!I5),"Não","Sim")) | P5: =IF(LEN(H5)=3,"Defeito encontrado",IF(I5="Sim","Falso alarme",IF(H5="—","Nenhum defeito apontado","")))
A6: =Apontamentos!C6 | B6: =IF(Apontamentos!$C6="","",Apontamentos!A6&"") | C6: =IF(B6="","",IFERROR(INDEX(Execuções!$C$2:$C$97,MATCH(B6,Execuções!$A$2:$A$97,0)),"ID?")) | D6: =IF(B6="","",IFERROR(INDEX(Execuções!$B$2:$B$97,MATCH(B6,Execuções!$A$2:$A$97,0)),"ID?")) | E6: =IF(B6="","",Apontamentos!D6) | F6: =IF(B6="","",Apontamentos!E6) | G6: =IF(B6="","",Apontamentos!G6&"") | H6: =IF('Avaliador 1'!F6='Avaliador 2'!F6,'Avaliador 1'!F6&"","") | I6: =IF('Avaliador 1'!G6='Avaliador 2'!G6,'Avaliador 1'!G6&"","") | J6: =IF('Avaliador 1'!H6='Avaliador 2'!H6,'Avaliador 1'!H6&"","") | K6: =IF('Avaliador 1'!I6='Avaliador 2'!I6,'Avaliador 1'!I6&"","") | M6: =IF('Avaliador 1'!J6='Avaliador 2'!J6,'Avaliador 1'!J6&"","") | N6: =IF(OR('Avaliador 1'!F6="",'Avaliador 2'!F6=""),"",IF(AND('Avaliador 1'!F6='Avaliador 2'!F6,'Avaliador 1'!G6='Avaliador 2'!G6,'Avaliador 1'!H6='Avaliador 2'!H6,'Avaliador 1'!I6='Avaliador 2'!I6),"Não","Sim")) | P6: =IF(LEN(H6)=3,"Defeito encontrado",IF(I6="Sim","Falso alarme",IF(H6="—","Nenhum defeito apontado","")))
A7: =Apontamentos!C7 | B7: =IF(Apontamentos!$C7="","",Apontamentos!A7&"") | C7: =IF(B7="","",IFERROR(INDEX(Execuções!$C$2:$C$97,MATCH(B7,Execuções!$A$2:$A$97,0)),"ID?")) | D7: =IF(B7="","",IFERROR(INDEX(Execuções!$B$2:$B$97,MATCH(B7,Execuções!$A$2:$A$97,0)),"ID?")) | E7: =IF(B7="","",Apontamentos!D7) | F7: =IF(B7="","",Apontamentos!E7) | G7: =IF(B7="","",Apontamentos!G7&"") | H7: =IF('Avaliador 1'!F7='Avaliador 2'!F7,'Avaliador 1'!F7&"","") | I7: =IF('Avaliador 1'!G7='Avaliador 2'!G7,'Avaliador 1'!G7&"","") | J7: =IF('Avaliador 1'!H7='Avaliador 2'!H7,'Avaliador 1'!H7&"","") | K7: =IF('Avaliador 1'!I7='Avaliador 2'!I7,'Avaliador 1'!I7&"","") | M7: =IF('Avaliador 1'!J7='Avaliador 2'!J7,'Avaliador 1'!J7&"","") | N7: =IF(OR('Avaliador 1'!F7="",'Avaliador 2'!F7=""),"",IF(AND('Avaliador 1'!F7='Avaliador 2'!F7,'Avaliador 1'!G7='Avaliador 2'!G7,'Avaliador 1'!H7='Avaliador 2'!H7,'Avaliador 1'!I7='Avaliador 2'!I7),"Não","Sim")) | P7: =IF(LEN(H7)=3,"Defeito encontrado",IF(I7="Sim","Falso alarme",IF(H7="—","Nenhum defeito apontado","")))
A8: =Apontamentos!C8 | B8: =IF(Apontamentos!$C8="","",Apontamentos!A8&"") | C8: =IF(B8="","",IFERROR(INDEX(Execuções!$C$2:$C$97,MATCH(B8,Execuções!$A$2:$A$97,0)),"ID?")) | D8: =IF(B8="","",IFERROR(INDEX(Execuções!$B$2:$B$97,MATCH(B8,Execuções!$A$2:$A$97,0)),"ID?")) | E8: =IF(B8="","",Apontamentos!D8) | F8: =IF(B8="","",Apontamentos!E8) | G8: =IF(B8="","",Apontamentos!G8&"") | H8: =IF('Avaliador 1'!F8='Avaliador 2'!F8,'Avaliador 1'!F8&"","") | I8: =IF('Avaliador 1'!G8='Avaliador 2'!G8,'Avaliador 1'!G8&"","") | J8: =IF('Avaliador 1'!H8='Avaliador 2'!H8,'Avaliador 1'!H8&"","") | K8: =IF('Avaliador 1'!I8='Avaliador 2'!I8,'Avaliador 1'!I8&"","") | M8: =IF('Avaliador 1'!J8='Avaliador 2'!J8,'Avaliador 1'!J8&"","") | N8: =IF(OR('Avaliador 1'!F8="",'Avaliador 2'!F8=""),"",IF(AND('Avaliador 1'!F8='Avaliador 2'!F8,'Avaliador 1'!G8='Avaliador 2'!G8,'Avaliador 1'!H8='Avaliador 2'!H8,'Avaliador 1'!I8='Avaliador 2'!I8),"Não","Sim")) | P8: =IF(LEN(H8)=3,"Defeito encontrado",IF(I8="Sim","Falso alarme",IF(H8="—","Nenhum defeito apontado","")))
A9: =Apontamentos!C9 | B9: =IF(Apontamentos!$C9="","",Apontamentos!A9&"") | C9: =IF(B9="","",IFERROR(INDEX(Execuções!$C$2:$C$97,MATCH(B9,Execuções!$A$2:$A$97,0)),"ID?")) | D9: =IF(B9="","",IFERROR(INDEX(Execuções!$B$2:$B$97,MATCH(B9,Execuções!$A$2:$A$97,0)),"ID?")) | E9: =IF(B9="","",Apontamentos!D9) | F9: =IF(B9="","",Apontamentos!E9) | G9: =IF(B9="","",Apontamentos!G9&"") | H9: =IF('Avaliador 1'!F9='Avaliador 2'!F9,'Avaliador 1'!F9&"","") | I9: =IF('Avaliador 1'!G9='Avaliador 2'!G9,'Avaliador 1'!G9&"","") | J9: =IF('Avaliador 1'!H9='Avaliador 2'!H9,'Avaliador 1'!H9&"","") | K9: =IF('Avaliador 1'!I9='Avaliador 2'!I9,'Avaliador 1'!I9&"","") | M9: =IF('Avaliador 1'!J9='Avaliador 2'!J9,'Avaliador 1'!J9&"","") | N9: =IF(OR('Avaliador 1'!F9="",'Avaliador 2'!F9=""),"",IF(AND('Avaliador 1'!F9='Avaliador 2'!F9,'Avaliador 1'!G9='Avaliador 2'!G9,'Avaliador 1'!H9='Avaliador 2'!H9,'Avaliador 1'!I9='Avaliador 2'!I9),"Não","Sim")) | P9: =IF(LEN(H9)=3,"Defeito encontrado",IF(I9="Sim","Falso alarme",IF(H9="—","Nenhum defeito apontado","")))
A10: =Apontamentos!C10 | B10: =IF(Apontamentos!$C10="","",Apontamentos!A10&"") | C10: =IF(B10="","",IFERROR(INDEX(Execuções!$C$2:$C$97,MATCH(B10,Execuções!$A$2:$A$97,0)),"ID?")) | D10: =IF(B10="","",IFERROR(INDEX(Execuções!$B$2:$B$97,MATCH(B10,Execuções!$A$2:$A$97,0)),"ID?")) | E10: =IF(B10="","",Apontamentos!D10) | F10: =IF(B10="","",Apontamentos!E10) | G10: =IF(B10="","",Apontamentos!G10&"") | H10: =IF('Avaliador 1'!F10='Avaliador 2'!F10,'Avaliador 1'!F10&"","") | I10: =IF('Avaliador 1'!G10='Avaliador 2'!G10,'Avaliador 1'!G10&"","") | J10: =IF('Avaliador 1'!H10='Avaliador 2'!H10,'Avaliador 1'!H10&"","") | K10: =IF('Avaliador 1'!I10='Avaliador 2'!I10,'Avaliador 1'!I10&"","") | M10: =IF('Avaliador 1'!J10='Avaliador 2'!J10,'Avaliador 1'!J10&"","") | N10: =IF(OR('Avaliador 1'!F10="",'Avaliador 2'!F10=""),"",IF(AND('Avaliador 1'!F10='Avaliador 2'!F10,'Avaliador 1'!G10='Avaliador 2'!G10,'Avaliador 1'!H10='Avaliador 2'!H10,'Avaliador 1'!I10='Avaliador 2'!I10),"Não","Sim")) | P10: =IF(LEN(H10)=3,"Defeito encontrado",IF(I10="Sim","Falso alarme",IF(H10="—","Nenhum defeito apontado","")))
A11: =Apontamentos!C11 | B11: =IF(Apontamentos!$C11="","",Apontamentos!A11&"") | C11: =IF(B11="","",IFERROR(INDEX(Execuções!$C$2:$C$97,MATCH(B11,Execuções!$A$2:$A$97,0)),"ID?")) | D11: =IF(B11="","",IFERROR(INDEX(Execuções!$B$2:$B$97,MATCH(B11,Execuções!$A$2:$A$97,0)),"ID?")) | E11: =IF(B11="","",Apontamentos!D11) | F11: =IF(B11="","",Apontamentos!E11) | G11: =IF(B11="","",Apontamentos!G11&"") | H11: =IF('Avaliador 1'!F11='Avaliador 2'!F11,'Avaliador 1'!F11&"","") | I11: =IF('Avaliador 1'!G11='Avaliador 2'!G11,'Avaliador 1'!G11&"","") | J11: =IF('Avaliador 1'!H11='Avaliador 2'!H11,'Avaliador 1'!H11&"","") | K11: =IF('Avaliador 1'!I11='Avaliador 2'!I11,'Avaliador 1'!I11&"","") | M11: =IF('Avaliador 1'!J11='Avaliador 2'!J11,'Avaliador 1'!J11&"","") | N11: =IF(OR('Avaliador 1'!F11="",'Avaliador 2'!F11=""),"",IF(AND('Avaliador 1'!F11='Avaliador 2'!F11,'Avaliador 1'!G11='Avaliador 2'!G11,'Avaliador 1'!H11='Avaliador 2'!H11,'Avaliador 1'!I11='Avaliador 2'!I11),"Não","Sim")) | P11: =IF(LEN(H11)=3,"Defeito encontrado",IF(I11="Sim","Falso alarme",IF(H11="—","Nenhum defeito apontado","")))
A12: =Apontamentos!C12 | B12: =IF(Apontamentos!$C12="","",Apontamentos!A12&"") | C12: =IF(B12="","",IFERROR(INDEX(Execuções!$C$2:$C$97,MATCH(B12,Execuções!$A$2:$A$97,0)),"ID?")) | D12: =IF(B12="","",IFERROR(INDEX(Execuções!$B$2:$B$97,MATCH(B12,Execuções!$A$2:$A$97,0)),"ID?")) | E12: =IF(B12="","",Apontamentos!D12) | F12: =IF(B12="","",Apontamentos!E12) | G12: =IF(B12="","",Apontamentos!G12&"") | H12: =IF('Avaliador 1'!F12='Avaliador 2'!F12,'Avaliador 1'!F12&"","") | I12: =IF('Avaliador 1'!G12='Avaliador 2'!G12,'Avaliador 1'!G12&"","") | J12: =IF('Avaliador 1'!H12='Avaliador 2'!H12,'Avaliador 1'!H12&"","") | K12: =IF('Avaliador 1'!I12='Avaliador 2'!I12,'Avaliador 1'!I12&"","") | M12: =IF('Avaliador 1'!J12='Avaliador 2'!J12,'Avaliador 1'!J12&"","") | N12: =IF(OR('Avaliador 1'!F12="",'Avaliador 2'!F12=""),"",IF(AND('Avaliador 1'!F12='Avaliador 2'!F12,'Avaliador 1'!G12='Avaliador 2'!G12,'Avaliador 1'!H12='Avaliador 2'!H12,'Avaliador 1'!I12='Avaliador 2'!I12),"Não","Sim")) | P12: =IF(LEN(H12)=3,"Defeito encontrado",IF(I12="Sim","Falso alarme",IF(H12="—","Nenhum defeito apontado","")))
A13: =Apontamentos!C13 | B13: =IF(Apontamentos!$C13="","",Apontamentos!A13&"") | C13: =IF(B13="","",IFERROR(INDEX(Execuções!$C$2:$C$97,MATCH(B13,Execuções!$A$2:$A$97,0)),"ID?")) | D13: =IF(B13="","",IFERROR(INDEX(Execuções!$B$2:$B$97,MATCH(B13,Execuções!$A$2:$A$97,0)),"ID?")) | E13: =IF(B13="","",Apontamentos!D13) | F13: =IF(B13="","",Apontamentos!E13) | G13: =IF(B13="","",Apontamentos!G13&"") | H13: =IF('Avaliador 1'!F13='Avaliador 2'!F13,'Avaliador 1'!F13&"","") | I13: =IF('Avaliador 1'!G13='Avaliador 2'!G13,'Avaliador 1'!G13&"","") | J13: =IF('Avaliador 1'!H13='Avaliador 2'!H13,'Avaliador 1'!H13&"","") | K13: =IF('Avaliador 1'!I13='Avaliador 2'!I13,'Avaliador 1'!I13&"","") | M13: =IF('Avaliador 1'!J13='Avaliador 2'!J13,'Avaliador 1'!J13&"","") | N13: =IF(OR('Avaliador 1'!F13="",'Avaliador 2'!F13=""),"",IF(AND('Avaliador 1'!F13='Avaliador 2'!F13,'Avaliador 1'!G13='Avaliador 2'!G13,'Avaliador 1'!H13='Avaliador 2'!H13,'Avaliador 1'!I13='Avaliador 2'!I13),"Não","Sim")) | P13: =IF(LEN(H13)=3,"Defeito encontrado",IF(I13="Sim","Falso alarme",IF(H13="—","Nenhum defeito apontado","")))
... A601: =Apontamentos!C601 | B601: =IF(Apontamentos!$C601="","",Apontamentos!A601&"") | C601: =IF(B601="","",IFERROR(INDEX(Execuções!$C$2:$C$97,MATCH(B601,Execuções!$A$2:$A$97,0)),"ID?")) | D601: =IF(B601="","",IFERROR(INDEX(Execuções!$B$2:$B$97,MATCH(B601,Execuções!$A$2:$A$97,0)),"ID?")) | E601: =IF(B601="","",Apontamentos!D601) | F601: =IF(B601="","",Apontamentos!E601) | G601: =IF(B601="","",Apontamentos!G601&"") | H601: =IF('Avaliador 1'!F601='Avaliador 2'!F601,'Avaliador 1'!F601&"","") | I601: =IF('Avaliador 1'!G601='Avaliador 2'!G601,'Avaliador 1'!G601&"","") | J601: =IF('Avaliador 1'!H601='Avaliador 2'!H601,'Avaliador 1'!H601&"","") | K601: =IF('Avaliador 1'!I601='Avaliador 2'!I601,'Avaliador 1'!I601&"","") | M601: =IF('Avaliador 1'!J601='Avaliador 2'!J601,'Avaliador 1'!J601&"","") | N601: =IF(OR('Avaliador 1'!F601="",'Avaliador 2'!F601=""),"",IF(AND('Avaliador 1'!F601='Avaliador 2'!F601,'Avaliador 1'!G601='Avaliador 2'!G601,'Avaliador 1'!H601='Avaliador 2'!H601,'Avaliador 1'!I601='Avaliador 2'!I601),"Não","Sim")) | P601: =IF(LEN(H601)=3,"Defeito encontrado",IF(I601="Sim","Falso alarme",IF(H601="—","Nenhum defeito apontado","")))

Sheet Defeitos não encontrados
A1: ID resposta | B1: Assistente | C1: Execução | D1: Programa | E1: Defeito | F1: Categoria | G1: Encontrado | H1: Não encontrado
A2: R008 | B2: Codex | C2: 1 | D2: banco | E2: D01 | F2: Valor-limite | G2: =IF(Execuções!$I$9="","",IF(COUNTIFS(Consenso!$B$2:$B$601,A2,Consenso!$H$2:$H$601,E2)>0,"Sim","Não")) | H2: =IF(G2="","",IF(G2="Não","Sim","Não"))
A3: R008 | B3: Codex | C3: 1 | D3: banco | E3: D02 | F3: Cálculo | G3: =IF(Execuções!$I$9="","",IF(COUNTIFS(Consenso!$B$2:$B$601,A3,Consenso!$H$2:$H$601,E3)>0,"Sim","Não")) | H3: =IF(G3="","",IF(G3="Não","Sim","Não"))
A4: R008 | B4: Codex | C4: 1 | D4: banco | E4: D03 | F4: Atualização de dados | G4: =IF(Execuções!$I$9="","",IF(COUNTIFS(Consenso!$B$2:$B$601,A4,Consenso!$H$2:$H$601,E4)>0,"Sim","Não")) | H4: =IF(G4="","",IF(G4="Não","Sim","Não"))
A5: R015 | B5: Codex | C5: 2 | D5: banco | E5: D01 | F5: Valor-limite | G5: =IF(Execuções!$I$16="","",IF(COUNTIFS(Consenso!$B$2:$B$601,A5,Consenso!$H$2:$H$601,E5)>0,"Sim","Não")) | H5: =IF(G5="","",IF(G5="Não","Sim","Não"))
A6: R015 | B6: Codex | C6: 2 | D6: banco | E6: D02 | F6: Cálculo | G6: =IF(Execuções!$I$16="","",IF(COUNTIFS(Consenso!$B$2:$B$601,A6,Consenso!$H$2:$H$601,E6)>0,"Sim","Não")) | H6: =IF(G6="","",IF(G6="Não","Sim","Não"))
A7: R015 | B7: Codex | C7: 2 | D7: banco | E7: D03 | F7: Atualização de dados | G7: =IF(Execuções!$I$16="","",IF(COUNTIFS(Consenso!$B$2:$B$601,A7,Consenso!$H$2:$H$601,E7)>0,"Sim","Não")) | H7: =IF(G7="","",IF(G7="Não","Sim","Não"))
A8: R024 | B8: Codex | C8: 3 | D8: banco | E8: D01 | F8: Valor-limite | G8: =IF(Execuções!$I$25="","",IF(COUNTIFS(Consenso!$B$2:$B$601,A8,Consenso!$H$2:$H$601,E8)>0,"Sim","Não")) | H8: =IF(G8="","",IF(G8="Não","Sim","Não"))
A9: R024 | B9: Codex | C9: 3 | D9: banco | E9: D02 | F9: Cálculo | G9: =IF(Execuções!$I$25="","",IF(COUNTIFS(Consenso!$B$2:$B$601,A9,Consenso!$H$2:$H$601,E9)>0,"Sim","Não")) | H9: =IF(G9="","",IF(G9="Não","Sim","Não"))
A10: R024 | B10: Codex | C10: 3 | D10: banco | E10: D03 | F10: Atualização de dados | G10: =IF(Execuções!$I$25="","",IF(COUNTIFS(Consenso!$B$2:$B$601,A10,Consenso!$H$2:$H$601,E10)>0,"Sim","Não")) | H10: =IF(G10="","",IF(G10="Não","Sim","Não"))
A11: R007 | B11: Codex | C11: 1 | D11: carrinho | E11: D04 | F11: Condição | G11: =IF(Execuções!$I$8="","",IF(COUNTIFS(Consenso!$B$2:$B$601,A11,Consenso!$H$2:$H$601,E11)>0,"Sim","Não")) | H11: =IF(G11="","",IF(G11="Não","Sim","Não"))
A12: R007 | B12: Codex | C12: 1 | D12: carrinho | E12: D05 | F12: Validação de entrada | G12: =IF(Execuções!$I$8="","",IF(COUNTIFS(Consenso!$B$2:$B$601,A12,Consenso!$H$2:$H$601,E12)>0,"Sim","Não")) | H12: =IF(G12="","",IF(G12="Não","Sim","Não"))
A13: R007 | B13: Codex | C13: 1 | D13: carrinho | E13: D06 | F13: Cálculo | G13: =IF(Execuções!$I$8="","",IF(COUNTIFS(Consenso!$B$2:$B$601,A13,Consenso!$H$2:$H$601,E13)>0,"Sim","Não")) | H13: =IF(G13="","",IF(G13="Não","Sim","Não"))
A14: R011 | B14: Codex | C14: 2 | D14: carrinho | E14: D04 | F14: Condição | G14: =IF(Execuções!$I$12="","",IF(COUNTIFS(Consenso!$B$2:$B$601,A14,Consenso!$H$2:$H$601,E14)>0,"Sim","Não")) | H14: =IF(G14="","",IF(G14="Não","Sim","Não"))
A15: R011 | B15: Codex | C15: 2 | D15: carrinho | E15: D05 | F15: Validação de entrada | G15: =IF(Execuções!$I$12="","",IF(COUNTIFS(Consenso!$B$2:$B$601,A15,Consenso!$H$2:$H$601,E15)>0,"Sim","Não")) | H15: =IF(G15="","",IF(G15="Não","Sim","Não"))
A16: R011 | B16: Codex | C16: 2 | D16: carrinho | E16: D06 | F16: Cálculo | G16: =IF(Execuções!$I$12="","",IF(COUNTIFS(Consenso!$B$2:$B$601,A16,Consenso!$H$2:$H$601,E16)>0,"Sim","Não")) | H16: =IF(G16="","",IF(G16="Não","Sim","Não"))
A17: R017 | B17: Codex | C17: 3 | D17: carrinho | E17: D04 | F17: Condição | G17: =IF(Execuções!$I$18="","",IF(COUNTIFS(Consenso!$B$2:$B$601,A17,Consenso!$H$2:$H$601,E17)>0,"Sim","Não")) | H17: =IF(G17="","",IF(G17="Não","Sim","Não"))
A18: R017 | B18: Codex | C18: 3 | D18: carrinho | E18: D05 | F18: Validação de entrada | G18: =IF(Execuções!$I$18="","",IF(COUNTIFS(Consenso!$B$2:$B$601,A18,Consenso!$H$2:$H$601,E18)>0,"Sim","Não")) | H18: =IF(G18="","",IF(G18="Não","Sim","Não"))
A19: R017 | B19: Codex | C19: 3 | D19: carrinho | E19: D06 | F19: Cálculo | G19: =IF(Execuções!$I$18="","",IF(COUNTIFS(Consenso!$B$2:$B$601,A19,Consenso!$H$2:$H$601,E19)>0,"Sim","Não")) | H19: =IF(G19="","",IF(G19="Não","Sim","Não"))
A20: R005 | B20: Codex | C20: 1 | D20: reservas | E20: D07 | F20: Valor-limite | G20: =IF(Execuções!$I$6="","",IF(COUNTIFS(Consenso!$B$2:$B$601,A20,Consenso!$H$2:$H$601,E20)>0,"Sim","Não")) | H20: =IF(G20="","",IF(G20="Não","Sim","Não"))
A21: R005 | B21: Codex | C21: 1 | D21: reservas | E21: D08 | F21: Validação de entrada | G21: =IF(Execuções!$I$6="","",IF(COUNTIFS(Consenso!$B$2:$B$601,A21,Consenso!$H$2:$H$601,E21)>0,"Sim","Não")) | H21: =IF(G21="","",IF(G21="Não","Sim","Não"))
A22: R005 | B22: Codex | C22: 1 | D22: reservas | E22: D09 | F22: Condição | G22: =IF(Execuções!$I$6="","",IF(COUNTIFS(Consenso!$B$2:$B$601,A22,Consenso!$H$2:$H$601,E22)>0,"Sim","Não")) | H22: =IF(G22="","",IF(G22="Não","Sim","Não"))
A23: R010 | B23: Codex | C23: 2 | D23: reservas | E23: D07 | F23: Valor-limite | G23: =IF(Execuções!$I$11="","",IF(COUNTIFS(Consenso!$B$2:$B$601,A23,Consenso!$H$2:$H$601,E23)>0,"Sim","Não")) | H23: =IF(G23="","",IF(G23="Não","Sim","Não"))
A24: R010 | B24: Codex | C24: 2 | D24: reservas | E24: D08 | F24: Validação de entrada | G24: =IF(Execuções!$I$11="","",IF(COUNTIFS(Consenso!$B$2:$B$601,A24,Consenso!$H$2:$H$601,E24)>0,"Sim","Não")) | H24: =IF(G24="","",IF(G24="Não","Sim","Não"))
A25: R010 | B25: Codex | C25: 2 | D25: reservas | E25: D09 | F25: Condição | G25: =IF(Execuções!$I$11="","",IF(COUNTIFS(Consenso!$B$2:$B$601,A25,Consenso!$H$2:$H$601,E25)>0,"Sim","Não")) | H25: =IF(G25="","",IF(G25="Não","Sim","Não"))
A26: R023 | B26: Codex | C26: 3 | D26: reservas | E26: D07 | F26: Valor-limite | G26: =IF(Execuções!$I$24="","",IF(COUNTIFS(Consenso!$B$2:$B$601,A26,Consenso!$H$2:$H$601,E26)>0,"Sim","Não")) | H26: =IF(G26="","",IF(G26="Não","Sim","Não"))
A27: R023 | B27: Codex | C27: 3 | D27: reservas | E27: D08 | F27: Validação de entrada | G27: =IF(Execuções!$I$24="","",IF(COUNTIFS(Consenso!$B$2:$B$601,A27,Consenso!$H$2:$H$601,E27)>0,"Sim","Não")) | H27: =IF(G27="","",IF(G27="Não","Sim","Não"))
A28: R023 | B28: Codex | C28: 3 | D28: reservas | E28: D09 | F28: Condição | G28: =IF(Execuções!$I$24="","",IF(COUNTIFS(Consenso!$B$2:$B$601,A28,Consenso!$H$2:$H$601,E28)>0,"Sim","Não")) | H28: =IF(G28="","",IF(G28="Não","Sim","Não"))
A29: R003 | B29: Codex | C29: 1 | D29: notas | E29: D10 | F29: Cálculo | G29: =IF(Execuções!$I$4="","",IF(COUNTIFS(Consenso!$B$2:$B$601,A29,Consenso!$H$2:$H$601,E29)>0,"Sim","Não")) | H29: =IF(G29="","",IF(G29="Não","Sim","Não"))
A30: R003 | B30: Codex | C30: 1 | D30: notas | E30: D11 | F30: Validação de entrada | G30: =IF(Execuções!$I$4="","",IF(COUNTIFS(Consenso!$B$2:$B$601,A30,Consenso!$H$2:$H$601,E30)>0,"Sim","Não")) | H30: =IF(G30="","",IF(G30="Não","Sim","Não"))
A31: R003 | B31: Codex | C31: 1 | D31: notas | E31: D12 | F31: Valor-limite | G31: =IF(Execuções!$I$4="","",IF(COUNTIFS(Consenso!$B$2:$B$601,A31,Consenso!$H$2:$H$601,E31)>0,"Sim","Não")) | H31: =IF(G31="","",IF(G31="Não","Sim","Não"))
A32: R012 | B32: Codex | C32: 2 | D32: notas | E32: D10 | F32: Cálculo | G32: =IF(Execuções!$I$13="","",IF(COUNTIFS(Consenso!$B$2:$B$601,A32,Consenso!$H$2:$H$601,E32)>0,"Sim","Não")) | H32: =IF(G32="","",IF(G32="Não","Sim","Não"))
A33: R012 | B33: Codex | C33: 2 | D33: notas | E33: D11 | F33: Validação de entrada | G33: =IF(Execuções!$I$13="","",IF(COUNTIFS(Consenso!$B$2:$B$601,A33,Consenso!$H$2:$H$601,E33)>0,"Sim","Não")) | H33: =IF(G33="","",IF(G33="Não","Sim","Não"))
A34: R012 | B34: Codex | C34: 2 | D34: notas | E34: D12 | F34: Valor-limite | G34: =IF(Execuções!$I$13="","",IF(COUNTIFS(Consenso!$B$2:$B$601,A34,Consenso!$H$2:$H$601,E34)>0,"Sim","Não")) | H34: =IF(G34="","",IF(G34="Não","Sim","Não"))
A35: R018 | B35: Codex | C35: 3 | D35: notas | E35: D10 | F35: Cálculo | G35: =IF(Execuções!$I$19="","",IF(COUNTIFS(Consenso!$B$2:$B$601,A35,Consenso!$H$2:$H$601,E35)>0,"Sim","Não")) | H35: =IF(G35="","",IF(G35="Não","Sim","Não"))
A36: R018 | B36: Codex | C36: 3 | D36: notas | E36: D11 | F36: Validação de entrada | G36: =IF(Execuções!$I$19="","",IF(COUNTIFS(Consenso!$B$2:$B$601,A36,Consenso!$H$2:$H$601,E36)>0,"Sim","Não")) | H36: =IF(G36="","",IF(G36="Não","Sim","Não"))
A37: R018 | B37: Codex | C37: 3 | D37: notas | E37: D12 | F37: Valor-limite | G37: =IF(Execuções!$I$19="","",IF(COUNTIFS(Consenso!$B$2:$B$601,A37,Consenso!$H$2:$H$601,E37)>0,"Sim","Não")) | H37: =IF(G37="","",IF(G37="Não","Sim","Não"))
A38: R029 | B38: Claude | C38: 1 | D38: banco | E38: D01 | F38: Valor-limite | G38: =IF(Execuções!$I$30="","",IF(COUNTIFS(Consenso!$B$2:$B$601,A38,Consenso!$H$2:$H$601,E38)>0,"Sim","Não")) | H38: =IF(G38="","",IF(G38="Não","Sim","Não"))
A39: R029 | B39: Claude | C39: 1 | D39: banco | E39: D02 | F39: Cálculo | G39: =IF(Execuções!$I$30="","",IF(COUNTIFS(Consenso!$B$2:$B$601,A39,Consenso!$H$2:$H$601,E39)>0,"Sim","Não")) | H39: =IF(G39="","",IF(G39="Não","Sim","Não"))
A40: R029 | B40: Claude | C40: 1 | D40: banco | E40: D03 | F40: Atualização de dados | G40: =IF(Execuções!$I$30="","",IF(COUNTIFS(Consenso!$B$2:$B$601,A40,Consenso!$H$2:$H$601,E40)>0,"Sim","Não")) | H40: =IF(G40="","",IF(G40="Não","Sim","Não"))
...

Sheet Métricas
A1: Métricas por assistente (Seção 4.8)
A2: Tudo é calculado a partir das abas Consenso e Defeitos não encontrados. Não digite nesta aba.
A4: 1. Visão geral
A5: Assistente | B5: Respostas registradas | C5: Execuções sem apontamentos | D5: Apontamentos analisados | E5: Defeitos semeados avaliados | F5: Defeitos encontrados | G5: Revocação | H5: Apontamentos de defeito | I5: Falsos alarmes | J5: Proporção de falsos alarmes | K5: Apontamentos alucinados | L5: Proporção de alucinados | M5: Alucinados em defeito encontrado | N5: Alucinados em falso alarme | O5: Alucinados sem defeito apontado | P5: Comentários corretos
A6: Codex | B6: =COUNTIFS(Execuções!$B$2:$B$97,A6,Execuções!$I$2:$I$97,"<>") -> 0 | C6: =COUNTIFS(Execuções!$B$2:$B$97,A6,Execuções!$P$2:$P$97,"Sim") -> 0 | D6: =SUMPRODUCT((Consenso!$D$2:$D$601="Codex")*(Consenso!$P$2:$P$601<>"")) -> 0 | E6: =COUNTIFS('Defeitos não encontrados'!$B$2:$B$145,A6,'Defeitos não encontrados'!$G$2:$G$145,"Sim")+COUNTIFS('Defeitos não encontrados'!$B$2:$B$145,A6,'Defeitos não encontrados'!$G$2:$G$145,"Não") -> 0 | F6: =COUNTIFS('Defeitos não encontrados'!$B$2:$B$145,A6,'Defeitos não encontrados'!$G$2:$G$145,"Sim") -> 0 | G6: =IFERROR(F6/E6,"") | H6: =SUMPRODUCT((Consenso!$D$2:$D$601="Codex")*((Consenso!$P$2:$P$601="Defeito encontrado")+(Consenso!$P$2:$P$601="Falso alarme"))) -> 0 | I6: =SUMPRODUCT((Consenso!$D$2:$D$601="Codex")*(Consenso!$P$2:$P$601="Falso alarme")) -> 0 | J6: =IFERROR(I6/H6,"") | K6: =SUMPRODUCT((Consenso!$D$2:$D$601="Codex")*(Consenso!$P$2:$P$601<>"")*(Consenso!$J$2:$J$601="Sim")) -> 0 | L6: =IFERROR(K6/D6,"") | M6: =SUMPRODUCT((Consenso!$D$2:$D$601="Codex")*(Consenso!$P$2:$P$601="Defeito encontrado")*(Consenso!$J$2:$J$601="Sim")) -> 0 | N6: =SUMPRODUCT((Consenso!$D$2:$D$601="Codex")*(Consenso!$P$2:$P$601="Falso alarme")*(Consenso!$J$2:$J$601="Sim")) -> 0 | O6: =SUMPRODUCT((Consenso!$D$2:$D$601="Codex")*(Consenso!$P$2:$P$601="Nenhum defeito apontado")*(Consenso!$J$2:$J$601="Sim")) -> 0 | P6: =SUMPRODUCT((Consenso!$D$2:$D$601="Codex")*(Consenso!$P$2:$P$601<>"")*(Consenso!$K$2:$K$601="Sim")) -> 0
A7: Claude | B7: =COUNTIFS(Execuções!$B$2:$B$97,A7,Execuções!$I$2:$I$97,"<>") -> 0 | C7: =COUNTIFS(Execuções!$B$2:$B$97,A7,Execuções!$P$2:$P$97,"Sim") -> 0 | D7: =SUMPRODUCT((Consenso!$D$2:$D$601="Claude")*(Consenso!$P$2:$P$601<>"")) -> 0 | E7: =COUNTIFS('Defeitos não encontrados'!$B$2:$B$145,A7,'Defeitos não encontrados'!$G$2:$G$145,"Sim")+COUNTIFS('Defeitos não encontrados'!$B$2:$B$145,A7,'Defeitos não encontrados'!$G$2:$G$145,"Não") -> 0 | F7: =COUNTIFS('Defeitos não encontrados'!$B$2:$B$145,A7,'Defeitos não encontrados'!$G$2:$G$145,"Sim") -> 0 | G7: =IFERROR(F7/E7,"") | H7: =SUMPRODUCT((Consenso!$D$2:$D$601="Claude")*((Consenso!$P$2:$P$601="Defeito encontrado")+(Consenso!$P$2:$P$601="Falso alarme"))) -> 0 | I7: =SUMPRODUCT((Consenso!$D$2:$D$601="Claude")*(Consenso!$P$2:$P$601="Falso alarme")) -> 0 | J7: =IFERROR(I7/H7,"") | K7: =SUMPRODUCT((Consenso!$D$2:$D$601="Claude")*(Consenso!$P$2:$P$601<>"")*(Consenso!$J$2:$J$601="Sim")) -> 0 | L7: =IFERROR(K7/D7,"") | M7: =SUMPRODUCT((Consenso!$D$2:$D$601="Claude")*(Consenso!$P$2:$P$601="Defeito encontrado")*(Consenso!$J$2:$J$601="Sim")) -> 0 | N7: =SUMPRODUCT((Consenso!$D$2:$D$601="Claude")*(Consenso!$P$2:$P$601="Falso alarme")*(Consenso!$J$2:$J$601="Sim")) -> 0 | O7: =SUMPRODUCT((Consenso!$D$2:$D$601="Claude")*(Consenso!$P$2:$P$601="Nenhum defeito apontado")*(Consenso!$J$2:$J$601="Sim")) -> 0 | P7: =SUMPRODUCT((Consenso!$D$2:$D$601="Claude")*(Consenso!$P$2:$P$601<>"")*(Consenso!$K$2:$K$601="Sim")) -> 0
A8: Antigravity | B8: =COUNTIFS(Execuções!$B$2:$B$97,A8,Execuções!$I$2:$I$97,"<>") -> 0 | C8: =COUNTIFS(Execuções!$B$2:$B$97,A8,Execuções!$P$2:$P$97,"Sim") -> 0 | D8: =SUMPRODUCT((Consenso!$D$2:$D$601="Antigravity")*(Consenso!$P$2:$P$601<>"")) -> 0 | E8: =COUNTIFS('Defeitos não encontrados'!$B$2:$B$145,A8,'Defeitos não encontrados'!$G$2:$G$145,"Sim")+COUNTIFS('Defeitos não encontrados'!$B$2:$B$145,A8,'Defeitos não encontrados'!$G$2:$G$145,"Não") -> 0 | F8: =COUNTIFS('Defeitos não encontrados'!$B$2:$B$145,A8,'Defeitos não encontrados'!$G$2:$G$145,"Sim") -> 0 | G8: =IFERROR(F8/E8,"") | H8: =SUMPRODUCT((Consenso!$D$2:$D$601="Antigravity")*((Consenso!$P$2:$P$601="Defeito encontrado")+(Consenso!$P$2:$P$601="Falso alarme"))) -> 0 | I8: =SUMPRODUCT((Consenso!$D$2:$D$601="Antigravity")*(Consenso!$P$2:$P$601="Falso alarme")) -> 0 | J8: =IFERROR(I8/H8,"") | K8: =SUMPRODUCT((Consenso!$D$2:$D$601="Antigravity")*(Consenso!$P$2:$P$601<>"")*(Consenso!$J$2:$J$601="Sim")) -> 0 | L8: =IFERROR(K8/D8,"") | M8: =SUMPRODUCT((Consenso!$D$2:$D$601="Antigravity")*(Consenso!$P$2:$P$601="Defeito encontrado")*(Consenso!$J$2:$J$601="Sim")) -> 0 | N8: =SUMPRODUCT((Consenso!$D$2:$D$601="Antigravity")*(Consenso!$P$2:$P$601="Falso alarme")*(Consenso!$J$2:$J$601="Sim")) -> 0 | O8: =SUMPRODUCT((Consenso!$D$2:$D$601="Antigravity")*(Consenso!$P$2:$P$601="Nenhum defeito apontado")*(Consenso!$J$2:$J$601="Sim")) -> 0 | P8: =SUMPRODUCT((Consenso!$D$2:$D$601="Antigravity")*(Consenso!$P$2:$P$601<>"")*(Consenso!$K$2:$K$601="Sim")) -> 0
A9: GitHub Copilot | B9: =COUNTIFS(Execuções!$B$2:$B$97,A9,Execuções!$I$2:$I$97,"<>") -> 0 | C9: =COUNTIFS(Execuções!$B$2:$B$97,A9,Execuções!$P$2:$P$97,"Sim") -> 0 | D9: =SUMPRODUCT((Consenso!$D$2:$D$601="GitHub Copilot")*(Consenso!$P$2:$P$601<>"")) -> 0 | E9: =COUNTIFS('Defeitos não encontrados'!$B$2:$B$145,A9,'Defeitos não encontrados'!$G$2:$G$145,"Sim")+COUNTIFS('Defeitos não encontrados'!$B$2:$B$145,A9,'Defeitos não encontrados'!$G$2:$G$145,"Não") -> 0 | F9: =COUNTIFS('Defeitos não encontrados'!$B$2:$B$145,A9,'Defeitos não encontrados'!$G$2:$G$145,"Sim") -> 0 | G9: =IFERROR(F9/E9,"") | H9: =SUMPRODUCT((Consenso!$D$2:$D$601="GitHub Copilot")*((Consenso!$P$2:$P$601="Defeito encontrado")+(Consenso!$P$2:$P$601="Falso alarme"))) -> 0 | I9: =SUMPRODUCT((Consenso!$D$2:$D$601="GitHub Copilot")*(Consenso!$P$2:$P$601="Falso alarme")) -> 0 | J9: =IFERROR(I9/H9,"") | K9: =SUMPRODUCT((Consenso!$D$2:$D$601="GitHub Copilot")*(Consenso!$P$2:$P$601<>"")*(Consenso!$J$2:$J$601="Sim")) -> 0 | L9: =IFERROR(K9/D9,"") | M9: =SUMPRODUCT((Consenso!$D$2:$D$601="GitHub Copilot")*(Consenso!$P$2:$P$601="Defeito encontrado")*(Consenso!$J$2:$J$601="Sim")) -> 0 | N9: =SUMPRODUCT((Consenso!$D$2:$D$601="GitHub Copilot")*(Consenso!$P$2:$P$601="Falso alarme")*(Consenso!$J$2:$J$601="Sim")) -> 0 | O9: =SUMPRODUCT((Consenso!$D$2:$D$601="GitHub Copilot")*(Consenso!$P$2:$P$601="Nenhum defeito apontado")*(Consenso!$J$2:$J$601="Sim")) -> 0 | P9: =SUMPRODUCT((Consenso!$D$2:$D$601="GitHub Copilot")*(Consenso!$P$2:$P$601<>"")*(Consenso!$K$2:$K$601="Sim")) -> 0
A10: Total | B10: =SUM(B6:B9) -> 0 | C10: =SUM(C6:C9) -> 0 | D10: =SUM(D6:D9) -> 0 | E10: =SUM(E6:E9) -> 0 | F10: =SUM(F6:F9) -> 0 | G10: =IFERROR(F10/E10,"") | H10: =SUM(H6:H9) -> 0 | I10: =SUM(I6:I9) -> 0 | J10: =IFERROR(I10/H10,"") | K10: =SUM(K6:K9) -> 0 | L10: =IFERROR(K10/D10,"") | M10: =SUM(M6:M9) -> 0 | N10: =SUM(N6:N9) -> 0 | O10: =SUM(O6:O9) -> 0 | P10: =SUM(P6:P9) -> 0
A11: Revocação = defeitos encontrados ÷ defeitos semeados avaliados (12 por execução nas versões defeituosas). Proporção de falsos alarmes = falsos alarmes ÷ apontamentos de defeito (defeito encontrado + falso alarme). Proporção de alucinados = alucinados ÷ todos os apontamentos. O apontamento que indica defeito é tratado como positivo.
A14: 2. Por versão do programa
A15: Assistente | B15: Apontamentos (correta) | C15: Falsos alarmes (correta) | D15: Alucinados (correta) | E15: % alucinados (correta) | F15: Apontamentos (defeituosa) | G15: Falsos alarmes (defeituosa) | H15: Alucinados (defeituosa) | I15: % alucinados (defeituosa)
A16: Codex | B16: =SUMPRODUCT((Consenso!$D$2:$D$601=$A16)*(Consenso!$F$2:$F$601="correta")*(Consenso!$P$2:$P$601<>"")) -> 0 | C16: =SUMPRODUCT((Consenso!$D$2:$D$601=$A16)*(Consenso!$F$2:$F$601="correta")*(Consenso!$P$2:$P$601="Falso alarme")) -> 0 | D16: =SUMPRODUCT((Consenso!$D$2:$D$601=$A16)*(Consenso!$F$2:$F$601="correta")*(Consenso!$P$2:$P$601<>"")*(Consenso!$J$2:$J$601="Sim")) -> 0 | E16: =IFERROR(D16/B16,"") | F16: =SUMPRODUCT((Consenso!$D$2:$D$601=$A16)*(Consenso!$F$2:$F$601="defeituosa")*(Consenso!$P$2:$P$601<>"")) -> 0 | G16: =SUMPRODUCT((Consenso!$D$2:$D$601=$A16)*(Consenso!$F$2:$F$601="defeituosa")*(Consenso!$P$2:$P$601="Falso alarme")) -> 0 | H16: =SUMPRODUCT((Consenso!$D$2:$D$601=$A16)*(Consenso!$F$2:$F$601="defeituosa")*(Consenso!$P$2:$P$601<>"")*(Consenso!$J$2:$J$601="Sim")) -> 0 | I16: =IFERROR(H16/F16,"")
A17: Claude | B17: =SUMPRODUCT((Consenso!$D$2:$D$601=$A17)*(Consenso!$F$2:$F$601="correta")*(Consenso!$P$2:$P$601<>"")) -> 0 | C17: =SUMPRODUCT((Consenso!$D$2:$D$601=$A17)*(Consenso!$F$2:$F$601="correta")*(Consenso!$P$2:$P$601="Falso alarme")) -> 0 | D17: =SUMPRODUCT((Consenso!$D$2:$D$601=$A17)*(Consenso!$F$2:$F$601="correta")*(Consenso!$P$2:$P$601<>"")*(Consenso!$J$2:$J$601="Sim")) -> 0 | E17: =IFERROR(D17/B17,"") | F17: =SUMPRODUCT((Consenso!$D$2:$D$601=$A17)*(Consenso!$F$2:$F$601="defeituosa")*(Consenso!$P$2:$P$601<>"")) -> 0 | G17: =SUMPRODUCT((Consenso!$D$2:$D$601=$A17)*(Consenso!$F$2:$F$601="defeituosa")*(Consenso!$P$2:$P$601="Falso alarme")) -> 0 | H17: =SUMPRODUCT((Consenso!$D$2:$D$601=$A17)*(Consenso!$F$2:$F$601="defeituosa")*(Consenso!$P$2:$P$601<>"")*(Consenso!$J$2:$J$601="Sim")) -> 0 | I17: =IFERROR(H17/F17,"")
A18: Antigravity | B18: =SUMPRODUCT((Consenso!$D$2:$D$601=$A18)*(Consenso!$F$2:$F$601="correta")*(Consenso!$P$2:$P$601<>"")) -> 0 | C18: =SUMPRODUCT((Consenso!$D$2:$D$601=$A18)*(Consenso!$F$2:$F$601="correta")*(Consenso!$P$2:$P$601="Falso alarme")) -> 0 | D18: =SUMPRODUCT((Consenso!$D$2:$D$601=$A18)*(Consenso!$F$2:$F$601="correta")*(Consenso!$P$2:$P$601<>"")*(Consenso!$J$2:$J$601="Sim")) -> 0 | E18: =IFERROR(D18/B18,"") | F18: =SUMPRODUCT((Consenso!$D$2:$D$601=$A18)*(Consenso!$F$2:$F$601="defeituosa")*(Consenso!$P$2:$P$601<>"")) -> 0 | G18: =SUMPRODUCT((Consenso!$D$2:$D$601=$A18)*(Consenso!$F$2:$F$601="defeituosa")*(Consenso!$P$2:$P$601="Falso alarme")) -> 0 | H18: =SUMPRODUCT((Consenso!$D$2:$D$601=$A18)*(Consenso!$F$2:$F$601="defeituosa")*(Consenso!$P$2:$P$601<>"")*(Consenso!$J$2:$J$601="Sim")) -> 0 | I18: =IFERROR(H18/F18,"")
A19: GitHub Copilot | B19: =SUMPRODUCT((Consenso!$D$2:$D$601=$A19)*(Consenso!$F$2:$F$601="correta")*(Consenso!$P$2:$P$601<>"")) -> 0 | C19: =SUMPRODUCT((Consenso!$D$2:$D$601=$A19)*(Consenso!$F$2:$F$601="correta")*(Consenso!$P$2:$P$601="Falso alarme")) -> 0 | D19: =SUMPRODUCT((Consenso!$D$2:$D$601=$A19)*(Consenso!$F$2:$F$601="correta")*(Consenso!$P$2:$P$601<>"")*(Consenso!$J$2:$J$601="Sim")) -> 0 | E19: =IFERROR(D19/B19,"") | F19: =SUMPRODUCT((Consenso!$D$2:$D$601=$A19)*(Consenso!$F$2:$F$601="defeituosa")*(Consenso!$P$2:$P$601<>"")) -> 0 | G19: =SUMPRODUCT((Consenso!$D$2:$D$601=$A19)*(Consenso!$F$2:$F$601="defeituosa")*(Consenso!$P$2:$P$601="Falso alarme")) -> 0 | H19: =SUMPRODUCT((Consenso!$D$2:$D$601=$A19)*(Consenso!$F$2:$F$601="defeituosa")*(Consenso!$P$2:$P$601<>"")*(Consenso!$J$2:$J$601="Sim")) -> 0 | I19: =IFERROR(H19/F19,"")
A20: Na versão correta, todo apontamento de defeito é falso alarme.
A23: 3. Variação entre as três execuções
A24: Assistente | B24: Revocação exec. 1 | C24: Revocação exec. 2 | D24: Revocação exec. 3 | E24: Falsos alarmes exec. 1 | F24: Falsos alarmes exec. 2 | G24: Falsos alarmes exec. 3 | H24: Alucinados exec. 1 | I24: Alucinados exec. 2 | J24: Alucinados exec. 3
A25: Codex | B25: =IFERROR(COUNTIFS('Defeitos não encontrados'!$B$2:$B$145,$A25,'Defeitos não encontrados'!$C$2:$C$145,1,'Defeitos não encontrados'!$G$2:$G$145,"Sim")/(COUNTIFS('Defeitos não encontrados'!$B$2:$B$145,$A25,'Defeitos não encontrados'!$C$2:$C$145,1,'Defeitos não encontrados'!$G$2:$G$145,"Sim")+COUNTIFS('Defeitos não encontrados'!$B$2:$B$145,$A25,'Defeitos não encontrados'!$C$2:$C$145,1,'Defeitos não encontrados'!$G$2:$G$145,"Não")),"") | C25: =IFERROR(COUNTIFS('Defeitos não encontrados'!$B$2:$B$145,$A25,'Defeitos não encontrados'!$C$2:$C$145,2,'Defeitos não encontrados'!$G$2:$G$145,"Sim")/(COUNTIFS('Defeitos não encontrados'!$B$2:$B$145,$A25,'Defeitos não encontrados'!$C$2:$C$145,2,'Defeitos não encontrados'!$G$2:$G$145,"Sim")+COUNTIFS('Defeitos não encontrados'!$B$2:$B$145,$A25,'Defeitos não encontrados'!$C$2:$C$145,2,'Defeitos não encontrados'!$G$2:$G$145,"Não")),"") | D25: =IFERROR(COUNTIFS('Defeitos não encontrados'!$B$2:$B$145,$A25,'Defeitos não encontrados'!$C$2:$C$145,3,'Defeitos não encontrados'!$G$2:$G$145,"Sim")/(COUNTIFS('Defeitos não encontrados'!$B$2:$B$145,$A25,'Defeitos não encontrados'!$C$2:$C$145,3,'Defeitos não encontrados'!$G$2:$G$145,"Sim")+COUNTIFS('Defeitos não encontrados'!$B$2:$B$145,$A25,'Defeitos não encontrados'!$C$2:$C$145,3,'Defeitos não encontrados'!$G$2:$G$145,"Não")),"") | E25: =SUMPRODUCT((Consenso!$D$2:$D$601=$A25)*(Consenso!$C$2:$C$601=1)*(Consenso!$P$2:$P$601="Falso alarme")) -> 0 | F25: =SUMPRODUCT((Consenso!$D$2:$D$601=$A25)*(Consenso!$C$2:$C$601=2)*(Consenso!$P$2:$P$601="Falso alarme")) -> 0 | G25: =SUMPRODUCT((Consenso!$D$2:$D$601=$A25)*(Consenso!$C$2:$C$601=3)*(Consenso!$P$2:$P$601="Falso alarme")) -> 0 | H25: =SUMPRODUCT((Consenso!$D$2:$D$601=$A25)*(Consenso!$C$2:$C$601=1)*(Consenso!$P$2:$P$601<>"")*(Consenso!$J$2:$J$601="Sim")) -> 0 | I25: =SUMPRODUCT((Consenso!$D$2:$D$601=$A25)*(Consenso!$C$2:$C$601=2)*(Consenso!$P$2:$P$601<>"")*(Consenso!$J$2:$J$601="Sim")) -> 0 | J25: =SUMPRODUCT((Consenso!$D$2:$D$601=$A25)*(Consenso!$C$2:$C$601=3)*(Consenso!$P$2:$P$601<>"")*(Consenso!$J$2:$J$601="Sim")) -> 0
A26: Claude | B26: =IFERROR(COUNTIFS('Defeitos não encontrados'!$B$2:$B$145,$A26,'Defeitos não encontrados'!$C$2:$C$145,1,'Defeitos não encontrados'!$G$2:$G$145,"Sim")/(COUNTIFS('Defeitos não encontrados'!$B$2:$B$145,$A26,'Defeitos não encontrados'!$C$2:$C$145,1,'Defeitos não encontrados'!$G$2:$G$145,"Sim")+COUNTIFS('Defeitos não encontrados'!$B$2:$B$145,$A26,'Defeitos não encontrados'!$C$2:$C$145,1,'Defeitos não encontrados'!$G$2:$G$145,"Não")),"") | C26: =IFERROR(COUNTIFS('Defeitos não encontrados'!$B$2:$B$145,$A26,'Defeitos não encontrados'!$C$2:$C$145,2,'Defeitos não encontrados'!$G$2:$G$145,"Sim")/(COUNTIFS('Defeitos não encontrados'!$B$2:$B$145,$A26,'Defeitos não encontrados'!$C$2:$C$145,2,'Defeitos não encontrados'!$G$2:$G$145,"Sim")+COUNTIFS('Defeitos não encontrados'!$B$2:$B$145,$A26,'Defeitos não encontrados'!$C$2:$C$145,2,'Defeitos não encontrados'!$G$2:$G$145,"Não")),"") | D26: =IFERROR(COUNTIFS('Defeitos não encontrados'!$B$2:$B$145,$A26,'Defeitos não encontrados'!$C$2:$C$145,3,'Defeitos não encontrados'!$G$2:$G$145,"Sim")/(COUNTIFS('Defeitos não encontrados'!$B$2:$B$145,$A26,'Defeitos não encontrados'!$C$2:$C$145,3,'Defeitos não encontrados'!$G$2:$G$145,"Sim")+COUNTIFS('Defeitos não encontrados'!$B$2:$B$145,$A26,'Defeitos não encontrados'!$C$2:$C$145,3,'Defeitos não encontrados'!$G$2:$G$145,"Não")),"") | E26: =SUMPRODUCT((Consenso!$D$2:$D$601=$A26)*(Consenso!$C$2:$C$601=1)*(Consenso!$P$2:$P$601="Falso alarme")) -> 0 | F26: =SUMPRODUCT((Consenso!$D$2:$D$601=$A26)*(Consenso!$C$2:$C$601=2)*(Consenso!$P$2:$P$601="Falso alarme")) -> 0 | G26: =SUMPRODUCT((Consenso!$D$2:$D$601=$A26)*(Consenso!$C$2:$C$601=3)*(Consenso!$P$2:$P$601="Falso alarme")) -> 0 | H26: =SUMPRODUCT((Consenso!$D$2:$D$601=$A26)*(Consenso!$C$2:$C$601=1)*(Consenso!$P$2:$P$601<>"")*(Consenso!$J$2:$J$601="Sim")) -> 0 | I26: =SUMPRODUCT((Consenso!$D$2:$D$601=$A26)*(Consenso!$C$2:$C$601=2)*(Consenso!$P$2:$P$601<>"")*(Consenso!$J$2:$J$601="Sim")) -> 0 | J26: =SUMPRODUCT((Consenso!$D$2:$D$601=$A26)*(Consenso!$C$2:$C$601=3)*(Consenso!$P$2:$P$601<>"")*(Consenso!$J$2:$J$601="Sim")) -> 0
A27: Antigravity | B27: =IFERROR(COUNTIFS('Defeitos não encontrados'!$B$2:$B$145,$A27,'Defeitos não encontrados'!$C$2:$C$145,1,'Defeitos não encontrados'!$G$2:$G$145,"Sim")/(COUNTIFS('Defeitos não encontrados'!$B$2:$B$145,$A27,'Defeitos não encontrados'!$C$2:$C$145,1,'Defeitos não encontrados'!$G$2:$G$145,"Sim")+COUNTIFS('Defeitos não encontrados'!$B$2:$B$145,$A27,'Defeitos não encontrados'!$C$2:$C$145,1,'Defeitos não encontrados'!$G$2:$G$145,"Não")),"") | C27: =IFERROR(COUNTIFS('Defeitos não encontrados'!$B$2:$B$145,$A27,'Defeitos não encontrados'!$C$2:$C$145,2,'Defeitos não encontrados'!$G$2:$G$145,"Sim")/(COUNTIFS('Defeitos não encontrados'!$B$2:$B$145,$A27,'Defeitos não encontrados'!$C$2:$C$145,2,'Defeitos não encontrados'!$G$2:$G$145,"Sim")+COUNTIFS('Defeitos não encontrados'!$B$2:$B$145,$A27,'Defeitos não encontrados'!$C$2:$C$145,2,'Defeitos não encontrados'!$G$2:$G$145,"Não")),"") | D27: =IFERROR(COUNTIFS('Defeitos não encontrados'!$B$2:$B$145,$A27,'Defeitos não encontrados'!$C$2:$C$145,3,'Defeitos não encontrados'!$G$2:$G$145,"Sim")/(COUNTIFS('Defeitos não encontrados'!$B$2:$B$145,$A27,'Defeitos não encontrados'!$C$2:$C$145,3,'Defeitos não encontrados'!$G$2:$G$145,"Sim")+COUNTIFS('Defeitos não encontrados'!$B$2:$B$145,$A27,'Defeitos não encontrados'!$C$2:$C$145,3,'Defeitos não encontrados'!$G$2:$G$145,"Não")),"") | E27: =SUMPRODUCT((Consenso!$D$2:$D$601=$A27)*(Consenso!$C$2:$C$601=1)*(Consenso!$P$2:$P$601="Falso alarme")) -> 0 | F27: =SUMPRODUCT((Consenso!$D$2:$D$601=$A27)*(Consenso!$C$2:$C$601=2)*(Consenso!$P$2:$P$601="Falso alarme")) -> 0 | G27: =SUMPRODUCT((Consenso!$D$2:$D$601=$A27)*(Consenso!$C$2:$C$601=3)*(Consenso!$P$2:$P$601="Falso alarme")) -> 0 | H27: =SUMPRODUCT((Consenso!$D$2:$D$601=$A27)*(Consenso!$C$2:$C$601=1)*(Consenso!$P$2:$P$601<>"")*(Consenso!$J$2:$J$601="Sim")) -> 0 | I27: =SUMPRODUCT((Consenso!$D$2:$D$601=$A27)*(Consenso!$C$2:$C$601=2)*(Consenso!$P$2:$P$601<>"")*(Consenso!$J$2:$J$601="Sim")) -> 0 | J27: =SUMPRODUCT((Consenso!$D$2:$D$601=$A27)*(Consenso!$C$2:$C$601=3)*(Consenso!$P$2:$P$601<>"")*(Consenso!$J$2:$J$601="Sim")) -> 0
